import bcrypt
from jose import JWTError, jwt
from datetime import datetime, timedelta, timezone
from typing import Optional
from fastapi import Depends, HTTPException, status
from fastapi.security import OAuth2PasswordBearer
from sqlmodel import select
from . import models
from .database import get_db
from sqlalchemy.ext.asyncio import AsyncSession

SECRET_KEY = "123api"
ALGORITHM = "HS256"
ACCESS_TOKEN_EXPIRE_MINUTES = 30

oauth2_scheme = OAuth2PasswordBearer(tokenUrl="users/token")

def verify_password(plain_password: str, hashed_password: str) -> bool:
    return bcrypt.checkpw(plain_password.encode('utf-8'), hashed_password.encode('utf-8'))

def get_password_hash(password: str) -> str:
    hashed_bytes = bcrypt.hashpw(password.encode('utf-8'), bcrypt.gensalt())
    return hashed_bytes.decode('utf-8')

def create_access_token(data: dict, expires_delta: Optional[timedelta] = None):
    to_encode = data.copy()
    if expires_delta:
        expire = datetime.now(timezone.utc) + expires_delta
    else:
        expire = datetime.now(timezone.utc) + timedelta(minutes=15)
    to_encode.update({"exp": expire})
    encoded_jwt = jwt.encode(to_encode, SECRET_KEY, algorithm=ALGORITHM)
    return encoded_jwt

async def get_current_user(token: str = Depends(oauth2_scheme), db: AsyncSession = Depends(get_db)):
    credentials_exception = HTTPException(
        status_code=status.HTTP_401_UNAUTHORIZED,
        detail="Could not validate credentials",
        headers={"WWW-Authenticate": "Bearer"},
    )
    try:
        payload = jwt.decode(token, SECRET_KEY, algorithms=[ALGORITHM])
        username: str = payload.get("sub")
        if username is None:
            raise credentials_exception
        token_data = models.TokenData(username=username)
    except JWTError:
        raise credentials_exception
    
    statement = select(models.User).where(models.User.username == token_data.username)
    results = await db.execute(statement)
    
    user = results.scalars().first()
    
    if user is None:
        raise credentials_exception
    return user